Workbook

Sheet Parametreler
A1: PERFORMANS VE GELİR PAYLAŞIMI MODELİ - MODEL PARAMETRELERİ VE ANA VERİLER
A2: Uluslararası lojistik operasyonları kâr dağıtım kuralları, maliyet/katsayı girdileri ve Ülke Müdürlüğü eşleşme ana tablosu.
A4: Kâr Paylaşım Kuralı & Oranları | B4: Parametre Kodu | C4: Değer / Oran | D4: Açıklama
A5: TR Merkez Payı (Hub Stratejik Fonu) | B5: ORAN_TR_HUB | C5: 0.2 | D5: Tüm rotalarda toplam kârın %20'si Türkiye Genel Merkezine (Hub) ayrılır.
A6: Şubeler Arası Dağıtılabilir Pay | B6: ORAN_DAGITILABILIR | C6: 0.8 | D6: Kalan net pay (%80), rotada yer alan şubeler arasında paylaştırılır.
A7: Tek Şube Kendi İşi (Satan = Operasyon) | B7: ORAN_TEK_SUBE | C7: 1 | D7: Satış ve operasyon aynı şubedeyse, kalan net payın tamamı tek şubeye yazılır.
A8: Yeni Müşteri - Satan Şube Payı | B8: ORAN_YENI_SATICI | C8: 0.6 | D8: Satan ve operasyon farklıysa, yeni müşteri kazanımında (P1, P2) satıcı şube payı.
A9: Yeni Müşteri - Operasyon Şubesi Payı | B9: ORAN_YENI_OPERASYON | C9: 0.4 | D9: Satan ve operasyon farklıysa, yeni müşteri operasyonunda (P1, P2) taşıyıcı şube payı.
A10: Düzenli Müşteri - Satan Şube Payı | B10: ORAN_DUZENLI_SATICI | C10: 0.4 | D10: Satan ve operasyon farklıysa, düzenli müşteri işlerinde (P3, P4) satıcı şube payı.
A11: Düzenli Müşteri - Operasyon Şubesi Payı | B11: ORAN_DUZENLI_OPERASYON | C11: 0.6 | D11: Satan ve operasyon farklıysa, düzenli müşteri operasyonunda (P3, P4) taşıyıcı şube payı.
A13: BİRİM OPERASYON VE HESAPLAMA KATSAYILARI
A14: Parametre Açıklaması | B14: Parametre Kodu | C14: Birim Değer | D14: Para Birimi / Ölçü | E14: Kullanım Amacı
A15: Ton Başına Baz Navlun Kârı | B15: KATSAYI_TON_KAR | C15: 340 | D15: € / Ton | E15: Taşınan yük başına baz lojistik kârı
A16: Km Başına Operasyonel Kâr Katkısı | B16: KATSAYI_KM_KATKI | C16: 1.25 | D16: € / Km | E16: Mesafe ve rota zorluğu kâr çarpanı
A17: Gümrük & Elleçleme Taban Kâr Primi | B17: KATSAYI_SABIT_PRIM | C17: 450 | D17: € / Sefer | E17: Her uluslararası operasyon başına taban katkı payı
A18: Gecikme Kesinti Oranı | B18: ORAN_GECIKME_PENALTI | C18: 0.08 | D18: Oran | E18: Teslimatta gecikme yaşanırsa operasyonel kâr düzeltmesi
A20: ŞUBE VE ÜLKE MÜDÜRLÜĞÜ ANA VERİ EŞLEŞTİRME TABLOSU
A21: Şube Kodu | B21: Şube Adı | C21: Bulunduğu Ülke | D21: Bölge | E21: Ülke Müdürü | F21: Dönemsel Kâr Hedefi (€) | G21: Hedef Teslimat Oranı (OTD) | H21: Stratejik Hedef Puanı | I21: Geçen Yıl Kârı (€) | J21: Boş Dönüş Oranı | K21: Özmal Filo Oranı
A22: DE-MUC | B22: Almanya Şubesi | C22: Almanya | D22: Batı Avrupa | E22: Markus Weber | F22: 28000 | G22: 0.95 | H22: 90 | I22: 25000 | J22: 0.105 | K22: 0.45
A23: IT-MIL | B23: İtalya Şubesi | C23: İtalya | D23: Güney Avrupa | E23: Matteo Rossi | F23: 14000 | G23: 0.94 | H23: 88 | I23: 13500 | J23: 0.14 | K23: 0.42
A24: FR-LYO | B24: Fransa Şubesi | C24: Fransa | D24: Batı Avrupa | E24: Jean Dupont | F24: 15000 | G24: 0.93 | H24: 85 | I24: 16500 | J24: 0.11 | K24: 0.38
A25: ES-MAD | B25: İspanya Şubesi | C25: İspanya | D25: Güney Avrupa | E25: Carlos Mendez | F25: 12500 | G25: 0.92 | H25: 86 | I25: 12000 | J25: 0.095 | K25: 0.48
A26: PL-WAW | B26: Polonya Şubesi | C26: Polonya | D26: Doğu Avrupa | E26: Piotr Kowalski | F26: 18000 | G26: 0.94 | H26: 92 | I26: 20500 | J26: 0.132 | K26: 0.35
A27: RO-BUC | B27: Romanya Şubesi | C27: Romanya | D27: Güneydoğu Avrupa | E27: Andrei Popescu | F27: 17000 | G27: 0.91 | H27: 84 | I27: 15500 | J27: 0.115 | K27: 0.52
A28: TR-IST | B28: Türkiye Hub | C28: Türkiye | D28: Merkez (Hub) | E28: Caner Yılmaz | F28: 48000 | G28: 0.96 | H28: 95 | I28: 47000 | J28: 0.08 | K28: 0.6
A30: 3 KUTULU NİHAİ ŞUBE MÜDÜRÜ PRİM SCORECARD MODEL PARAMETRELERİ
A31: KUTU 1: MERDİVENLİ FİNANSAL BÜYÜME (YoY) PARAMETRELERİ
A32: Kademe / Performans Aralığı | B32: Alt Sınır | C32: Üst Sınır | D32: Prim Oranı (% Kâr) | E32: Açıklama
A33: Kademe 1 (<%90) | B33: 0 | C33: 0.899 | D33: 0 | E33: Asgari finansal başarı eşiğinin altı (Prim yok)
A34: Kademe 2 (%90 - %99.9) | B34: 0.9 | C34: 0.999 | D34: 0.05 | E34: %90-%99.9 arası gerçekleşmede %5 kâr primi
A35: Kademe 3 (%100 - %114.9) | B35: 1 | C35: 1.149 | D35: 0.1 | E35: %100-%114.9 arası gerçekleşmede %10 kâr primi
A36: Kademe 4 (%115 - %125) | B36: 1.15 | C36: 1.25 | D36: 0.15 | E36: %115-%125 arası gerçekleşmede %15 kâr primi
A37: Kademe 5 (>%125) | B37: 1.25 | C37: 9.99 | D37: 0 | E37: Tavan aşımı / Bütçe dışı katsayı (%0)
A39: KUTU 2: HACİM (TON) X OTD KALİTE ÇARPANI PARAMETRELERİ
A40: Parametre Tanımı | B40: Parametre Kodu | C40: Değer / Çarpan | D40: Birim / Ölçü | E40: Açıklama
A41: Kutu 2 Finansal Başarı Barajı | B41: KUTU2_BARAJ_ESIK | C41: 0.9 | D41: Oran | E41: Kutu 2 hak edişi için asgari finansal baraj (>=%90)
A42: Ton Başına Baz Prim Tutarı | B42: KUTU2_TON_PRIM | C42: 5 | D42: € / Ton | E42: Elleçlenen yük tonajı başına baz prim katsayısı
A43: OTD Mükemmel Çarpanı (>=%95) | B43: KUTU2_OTD_MUKEMMEL | C43: 1.25 | D43: Çarpan | E43: Zamanında teslimat %95 ve üzeri ise kalite çarpanı
A44: OTD Başarılı Çarpanı (%90 - %94.9) | B44: KUTU2_OTD_BASARILI | C44: 1 | D44: Çarpan | E44: Zamanında teslimat %90-%94.9 ise baz kalite çarpanı
A45: OTD Kabul Edilebilir (%85 - %89.9) | B45: KUTU2_OTD_KABUL | C45: 0.75 | D45: Çarpan | E45: Zamanında teslimat %85-%89.9 ise indirimli çarpan
...

Sheet İşlemler
A1: ULUSLARARASI LOJİSTİK OPERASYONLARI VE KÂR DAĞITIM İŞLEM DEFTERİ
A2: Rotalara göre tonaj ve mesafe bazlı toplam kâr, merkez fonu (%20) ve Satan/Taşıyan şube kâr paylaşım hesaplamaları.
A4: İşlem ID | B4: Tarih | C4: Çıkış Ülkesi | D4: Varış Ülkesi | E4: Müşteri Profili | F4: İşlemi Satan Şube | G4: Satan Ülke Müdürü | H4: Operasyonu Yürüten Şube | I4: Operasyon Ülke Müdürü | J4: Yük Tonajı (Ton) | K4: Mesafe (Km) | L4: Zamanında Teslimat? | M4: Toplam Kâr (€) | N4: TR Hub Payı (%20) (€) | O4: Kalan Dağıtılabilir Pay (€) | P4: Paylaşım Türü | Q4: Satan Şube Payı (€) | R4: Operasyon Şube Payı (€) | S4: Mutabakat Kontrolü (€)
A5: TRX-2026-001 | B5: 46056 | C5: Almanya | D5: Türkiye | E5: P1 | F5: DE-MUC | G5: {=_xlfn.XLOOKUP(F5, Parametreler!$A$22:$A$28, Parametreler!$E$22:$E$28)} -> Markus Weber | H5: TR-IST | I5: {=_xlfn.XLOOKUP(H5, Parametreler!$A$22:$A$28, Parametreler!$E$22:$E$28)} -> Caner Yılmaz | J5: 22.5 | K5: 2250 | L5: Evet | M5: =ROUND((J5*Parametreler!$C$15 + K5*Parametreler!$C$16 + Parametreler!$C$17)*IF(L5="Evet", 1, 1-Parametreler!$C$18), 2) -> 10912.5 | N5: =ROUND(M5*Parametreler!$C$5, 2) -> 2182.5 | O5: =M5-N5 -> 8730 | P5: =IF(F5=H5, "Kendi İşi (Tek Şube)", "Ortak Operasyon") -> Ortak Operasyon | Q5: =ROUND(IF(F5=H5, O5*Parametreler!$C$7, IF(OR(E5="P1", E5="P2"), O5*Parametreler!$C$8, O5*Parametreler!$C$10)), 2) -> 5238 | R5: =ROUND(IF(F5=H5, 0, IF(OR(E5="P1", E5="P2"), O5*Parametreler!$C$9, O5*Parametreler!$C$11)), 2) -> 3492 | S5: =ROUND(N5+Q5+R5-M5, 2) -> 0
A6: TRX-2026-002 | B6: 46058 | C6: Türkiye | D6: Almanya | E6: P2 | F6: TR-IST | G6: {=_xlfn.XLOOKUP(F6, Parametreler!$A$22:$A$28, Parametreler!$E$22:$E$28)} -> Caner Yılmaz | H6: DE-MUC | I6: {=_xlfn.XLOOKUP(H6, Parametreler!$A$22:$A$28, Parametreler!$E$22:$E$28)} -> Markus Weber | J6: 24 | K6: 2250 | L6: Evet | M6: =ROUND((J6*Parametreler!$C$15 + K6*Parametreler!$C$16 + Parametreler!$C$17)*IF(L6="Evet", 1, 1-Parametreler!$C$18), 2) -> 11422.5 | N6: =ROUND(M6*Parametreler!$C$5, 2) -> 2284.5 | O6: =M6-N6 -> 9138 | P6: =IF(F6=H6, "Kendi İşi (Tek Şube)", "Ortak Operasyon") -> Ortak Operasyon | Q6: =ROUND(IF(F6=H6, O6*Parametreler!$C$7, IF(OR(E6="P1", E6="P2"), O6*Parametreler!$C$8, O6*Parametreler!$C$10)), 2) -> 5482.8 | R6: =ROUND(IF(F6=H6, 0, IF(OR(E6="P1", E6="P2"), O6*Parametreler!$C$9, O6*Parametreler!$C$11)), 2) -> 3655.2 | S6: =ROUND(N6+Q6+R6-M6, 2) -> 0
A7: TRX-2026-003 | B7: 46061 | C7: İtalya | D7: Fransa | E7: P3 | F7: IT-MIL | G7: {=_xlfn.XLOOKUP(F7, Parametreler!$A$22:$A$28, Parametreler!$E$22:$E$28)} -> Matteo Rossi | H7: FR-LYO | I7: {=_xlfn.XLOOKUP(H7, Parametreler!$A$22:$A$28, Parametreler!$E$22:$E$28)} -> Jean Dupont | J7: 18 | K7: 450 | L7: Evet | M7: =ROUND((J7*Parametreler!$C$15 + K7*Parametreler!$C$16 + Parametreler!$C$17)*IF(L7="Evet", 1, 1-Parametreler!$C$18), 2) -> 7132.5 | N7: =ROUND(M7*Parametreler!$C$5, 2) -> 1426.5 | O7: =M7-N7 -> 5706 | P7: =IF(F7=H7, "Kendi İşi (Tek Şube)", "Ortak Operasyon") -> Ortak Operasyon | Q7: =ROUND(IF(F7=H7, O7*Parametreler!$C$7, IF(OR(E7="P1", E7="P2"), O7*Parametreler!$C$8, O7*Parametreler!$C$10)), 2) -> 2282.4 | R7: =ROUND(IF(F7=H7, 0, IF(OR(E7="P1", E7="P2"), O7*Parametreler!$C$9, O7*Parametreler!$C$11)), 2) -> 3423.6 | S7: =ROUND(N7+Q7+R7-M7, 2) -> 0
A8: TRX-2026-004 | B8: 46064 | C8: Fransa | D8: İspanya | E8: P4 | F8: FR-LYO | G8: {=_xlfn.XLOOKUP(F8, Parametreler!$A$22:$A$28, Parametreler!$E$22:$E$28)} -> Jean Dupont | H8: ES-MAD | I8: {=_xlfn.XLOOKUP(H8, Parametreler!$A$22:$A$28, Parametreler!$E$22:$E$28)} -> Carlos Mendez | J8: 19.5 | K8: 1180 | L8: Evet | M8: =ROUND((J8*Parametreler!$C$15 + K8*Parametreler!$C$16 + Parametreler!$C$17)*IF(L8="Evet", 1, 1-Parametreler!$C$18), 2) -> 8555 | N8: =ROUND(M8*Parametreler!$C$5, 2) -> 1711 | O8: =M8-N8 -> 6844 | P8: =IF(F8=H8, "Kendi İşi (Tek Şube)", "Ortak Operasyon") -> Ortak Operasyon | Q8: =ROUND(IF(F8=H8, O8*Parametreler!$C$7, IF(OR(E8="P1", E8="P2"), O8*Parametreler!$C$8, O8*Parametreler!$C$10)), 2) -> 2737.6 | R8: =ROUND(IF(F8=H8, 0, IF(OR(E8="P1", E8="P2"), O8*Parametreler!$C$9, O8*Parametreler!$C$11)), 2) -> 4106.4 | S8: =ROUND(N8+Q8+R8-M8, 2) -> 0
A9: TRX-2026-005 | B9: 46067 | C9: Polonya | D9: Romanya | E9: P1 | F9: PL-WAW | G9: {=_xlfn.XLOOKUP(F9, Parametreler!$A$22:$A$28, Parametreler!$E$22:$E$28)} -> Piotr Kowalski | H9: RO-BUC | I9: {=_xlfn.XLOOKUP(H9, Parametreler!$A$22:$A$28, Parametreler!$E$22:$E$28)} -> Andrei Popescu | J9: 21 | K9: 1080 | L9: Hayır | M9: =ROUND((J9*Parametreler!$C$15 + K9*Parametreler!$C$16 + Parametreler!$C$17)*IF(L9="Evet", 1, 1-Parametreler!$C$18), 2) -> 8224.8 | N9: =ROUND(M9*Parametreler!$C$5, 2) -> 1644.96 | O9: =M9-N9 -> 6579.84 | P9: =IF(F9=H9, "Kendi İşi (Tek Şube)", "Ortak Operasyon") -> Ortak Operasyon | Q9: =ROUND(IF(F9=H9, O9*Parametreler!$C$7, IF(OR(E9="P1", E9="P2"), O9*Parametreler!$C$8, O9*Parametreler!$C$10)), 2) -> 3947.9 | R9: =ROUND(IF(F9=H9, 0, IF(OR(E9="P1", E9="P2"), O9*Parametreler!$C$9, O9*Parametreler!$C$11)), 2) -> 2631.94 | S9: =ROUND(N9+Q9+R9-M9, 2) -> 0
A10: TRX-2026-006 | B10: 46071 | C10: Türkiye | D10: İtalya | E10: P2 | F10: TR-IST | G10: {=_xlfn.XLOOKUP(F10, Parametreler!$A$22:$A$28, Parametreler!$E$22:$E$28)} -> Caner Yılmaz | H10: IT-MIL | I10: {=_xlfn.XLOOKUP(H10, Parametreler!$A$22:$A$28, Parametreler!$E$22:$E$28)} -> Matteo Rossi | J10: 23 | K10: 1920 | L10: Evet | M10: =ROUND((J10*Parametreler!$C$15 + K10*Parametreler!$C$16 + Parametreler!$C$17)*IF(L10="Evet", 1, 1-Parametreler!$C$18), 2) -> 10670 | N10: =ROUND(M10*Parametreler!$C$5, 2) -> 2134 | O10: =M10-N10 -> 8536 | P10: =IF(F10=H10, "Kendi İşi (Tek Şube)", "Ortak Operasyon") -> Ortak Operasyon | Q10: =ROUND(IF(F10=H10, O10*Parametreler!$C$7, IF(OR(E10="P1", E10="P2"), O10*Parametreler!$C$8, O10*Parametreler!$C$10)), 2) -> 5121.6 | R10: =ROUND(IF(F10=H10, 0, IF(OR(E10="P1", E10="P2"), O10*Parametreler!$C$9, O10*Parametreler!$C$11)), 2) -> 3414.4 | S10: =ROUND(N10+Q10+R10-M10, 2) -> 0
A11: TRX-2026-007 | B11: 46074 | C11: Almanya | D11: Polonya | E11: P3 | F11: DE-MUC | G11: {=_xlfn.XLOOKUP(F11, Parametreler!$A$22:$A$28, Parametreler!$E$22:$E$28)} -> Markus Weber | H11: PL-WAW | I11: {=_xlfn.XLOOKUP(H11, Parametreler!$A$22:$A$28, Parametreler!$E$22:$E$28)} -> Piotr Kowalski | J11: 16.5 | K11: 820 | L11: Evet | M11: =ROUND((J11*Parametreler!$C$15 + K11*Parametreler!$C$16 + Parametreler!$C$17)*IF(L11="Evet", 1, 1-Parametreler!$C$18), 2) -> 7085 | N11: =ROUND(M11*Parametreler!$C$5, 2) -> 1417 | O11: =M11-N11 -> 5668 | P11: =IF(F11=H11, "Kendi İşi (Tek Şube)", "Ortak Operasyon") -> Ortak Operasyon | Q11: =ROUND(IF(F11=H11, O11*Parametreler!$C$7, IF(OR(E11="P1", E11="P2"), O11*Parametreler!$C$8, O11*Parametreler!$C$10)), 2) -> 2267.2 | R11: =ROUND(IF(F11=H11, 0, IF(OR(E11="P1", E11="P2"), O11*Parametreler!$C$9, O11*Parametreler!$C$11)), 2) -> 3400.8 | S11: =ROUND(N11+Q11+R11-M11, 2) -> 0
A12: TRX-2026-008 | B12: 46078 | C12: İspanya | D12: İspanya | E12: P4 | F12: ES-MAD | G12: {=_xlfn.XLOOKUP(F12, Parametreler!$A$22:$A$28, Parametreler!$E$22:$E$28)} -> Carlos Mendez | H12: ES-MAD | I12: {=_xlfn.XLOOKUP(H12, Parametreler!$A$22:$A$28, Parametreler!$E$22:$E$28)} -> Carlos Mendez | J12: 20 | K12: 620 | L12: Evet | M12: =ROUND((J12*Parametreler!$C$15 + K12*Parametreler!$C$16 + Parametreler!$C$17)*IF(L12="Evet", 1, 1-Parametreler!$C$18), 2) -> 8025 | N12: =ROUND(M12*Parametreler!$C$5, 2) -> 1605 | O12: =M12-N12 -> 6420 | P12: =IF(F12=H12, "Kendi İşi (Tek Şube)", "Ortak Operasyon") -> Kendi İşi (Tek Şube) | Q12: =ROUND(IF(F12=H12, O12*Parametreler!$C$7, IF(OR(E12="P1", E12="P2"), O12*Parametreler!$C$8, O12*Parametreler!$C$10)), 2) -> 6420 | R12: =ROUND(IF(F12=H12, 0, IF(OR(E12="P1", E12="P2"), O12*Parametreler!$C$9, O12*Parametreler!$C$11)), 2) -> 0 | S12: =ROUND(N12+Q12+R12-M12, 2) -> 0
A13: TRX-2026-009 | B13: 46083 | C13: Romanya | D13: Türkiye | E13: P1 | F13: RO-BUC | G13: {=_xlfn.XLOOKUP(F13, Parametreler!$A$22:$A$28, Parametreler!$E$22:$E$28)} -> Andrei Popescu | H13: TR-IST | I13: {=_xlfn.XLOOKUP(H13, Parametreler!$A$22:$A$28, Parametreler!$E$22:$E$28)} -> Caner Yılmaz | J13: 22 | K13: 680 | L13: Evet | M13: =ROUND((J13*Parametreler!$C$15 + K13*Parametreler!$C$16 + Parametreler!$C$17)*IF(L13="Evet", 1, 1-Parametreler!$C$18), 2) -> 8780 | N13: =ROUND(M13*Parametreler!$C$5, 2) -> 1756 | O13: =M13-N13 -> 7024 | P13: =IF(F13=H13, "Kendi İşi (Tek Şube)", "Ortak Operasyon") -> Ortak Operasyon | Q13: =ROUND(IF(F13=H13, O13*Parametreler!$C$7, IF(OR(E13="P1", E13="P2"), O13*Parametreler!$C$8, O13*Parametreler!$C$10)), 2) -> 4214.4 | R13: =ROUND(IF(F13=H13, 0, IF(OR(E13="P1", E13="P2"), O13*Parametreler!$C$9, O13*Parametreler!$C$11)), 2) -> 2809.6 | S13: =ROUND(N13+Q13+R13-M13, 2) -> 0
A14: TRX-2026-010 | B14: 46087 | C14: İtalya | D14: Almanya | E14: P2 | F14: IT-MIL | G14: {=_xlfn.XLOOKUP(F14, Parametreler!$A$22:$A$28, Parametreler!$E$22:$E$28)} -> Matteo Rossi | H14: DE-MUC | I14: {=_xlfn.XLOOKUP(H14, Parametreler!$A$22:$A$28, Parametreler!$E$22:$E$28)} -> Markus Weber | J14: 17.5 | K14: 650 | L14: Hayır | M14: =ROUND((J14*Parametreler!$C$15 + K14*Parametreler!$C$16 + Parametreler!$C$17)*IF(L14="Evet", 1, 1-Parametreler!$C$18), 2) -> 6635.5 | N14: =ROUND(M14*Parametreler!$C$5, 2) -> 1327.1 | O14: =M14-N14 -> 5308.4 | P14: =IF(F14=H14, "Kendi İşi (Tek Şube)", "Ortak Operasyon") -> Ortak Operasyon | Q14: =ROUND(IF(F14=H14, O14*Parametreler!$C$7, IF(OR(E14="P1", E14="P2"), O14*Parametreler!$C$8, O14*Parametreler!$C$10)), 2) -> 3185.04 | R14: =ROUND(IF(F14=H14, 0, IF(OR(E14="P1", E14="P2"), O14*Parametreler!$C$9, O14*Parametreler!$C$11)), 2) -> 2123.36 | S14: =ROUND(N14+Q14+R14-M14, 2) -> 0
A15: TRX-2026-011 | B15: 46091 | C15: Fransa | D15: Fransa | E15: P3 | F15: FR-LYO | G15: {=_xlfn.XLOOKUP(F15, Parametreler!$A$22:$A$28, Parametreler!$E$22:$E$28)} -> Jean Dupont | H15: FR-LYO | I15: {=_xlfn.XLOOKUP(H15, Parametreler!$A$22:$A$28, Parametreler!$E$22:$E$28)} -> Jean Dupont | J15: 19 | K15: 480 | L15: Evet | M15: =ROUND((J15*Parametreler!$C$15 + K15*Parametreler!$C$16 + Parametreler!$C$17)*IF(L15="Evet", 1, 1-Parametreler!$C$18), 2) -> 7510 | N15: =ROUND(M15*Parametreler!$C$5, 2) -> 1502 | O15: =M15-N15 -> 6008 | P15: =IF(F15=H15, "Kendi İşi (Tek Şube)", "Ortak Operasyon") -> Kendi İşi (Tek Şube) | Q15: =ROUND(IF(F15=H15, O15*Parametreler!$C$7, IF(OR(E15="P1", E15="P2"), O15*Parametreler!$C$8, O15*Parametreler!$C$10)), 2) -> 6008 | R15: =ROUND(IF(F15=H15, 0, IF(OR(E15="P1", E15="P2"), O15*Parametreler!$C$9, O15*Parametreler!$C$11)), 2) -> 0 | S15: =ROUND(N15+Q15+R15-M15, 2) -> 0
A16: TRX-2026-012 | B16: 46095 | C16: Almanya | D16: Romanya | E16: P4 | F16: DE-MUC | G16: {=_xlfn.XLOOKUP(F16, Parametreler!$A$22:$A$28, Parametreler!$E$22:$E$28)} -> Markus Weber | H16: RO-BUC | I16: {=_xlfn.XLOOKUP(H16, Parametreler!$A$22:$A$28, Parametreler!$E$22:$E$28)} -> Andrei Popescu | J16: 21.5 | K16: 1540 | L16: Evet | M16: =ROUND((J16*Parametreler!$C$15 + K16*Parametreler!$C$16 + Parametreler!$C$17)*IF(L16="Evet", 1, 1-Parametreler!$C$18), 2) -> 9685 | N16: =ROUND(M16*Parametreler!$C$5, 2) -> 1937 | O16: =M16-N16 -> 7748 | P16: =IF(F16=H16, "Kendi İşi (Tek Şube)", "Ortak Operasyon") -> Ortak Operasyon | Q16: =ROUND(IF(F16=H16, O16*Parametreler!$C$7, IF(OR(E16="P1", E16="P2"), O16*Parametreler!$C$8, O16*Parametreler!$C$10)), 2) -> 3099.2 | R16: =ROUND(IF(F16=H16, 0, IF(OR(E16="P1", E16="P2"), O16*Parametreler!$C$9, O16*Parametreler!$C$11)), 2) -> 4648.8 | S16: =ROUND(N16+Q16+R16-M16, 2) -> 0
... A22: TRX-2026-018 | B22: 46126 | C22: Romanya | D22: Polonya | E22: P2 | F22: RO-BUC | G22: {=_xlfn.XLOOKUP(F22, Parametreler!$A$22:$A$28, Parametreler!$E$22:$E$28)} -> Andrei Popescu | H22: PL-WAW | I22: {=_xlfn.XLOOKUP(H22, Parametreler!$A$22:$A$28, Parametreler!$E$22:$E$28)} -> Piotr Kowalski | J22: 19 | K22: 1080 | L22: Evet | M22: =ROUND((J22*Parametreler!$C$15 + K22*Parametreler!$C$16 + Parametreler!$C$17)*IF(L22="Evet", 1, 1-Parametreler!$C$18), 2) -> 8260 | N22: =ROUND(M22*Parametreler!$C$5, 2) -> 1652 | O22: =M22-N22 -> 6608 | P22: =IF(F22=H22, "Kendi İşi (Tek Şube)", "Ortak Operasyon") -> Ortak Operasyon | Q22: =ROUND(IF(F22=H22, O22*Parametreler!$C$7, IF(OR(E22="P1", E22="P2"), O22*Parametreler!$C$8, O22*Parametreler!$C$10)), 2) -> 3964.8 | R22: =ROUND(IF(F22=H22, 0, IF(OR(E22="P1", E22="P2"), O22*Parametreler!$C$9, O22*Parametreler!$C$11)), 2) -> 2643.2 | S22: =ROUND(N22+Q22+R22-M22, 2) -> 0
A23: GENEL TOPLAM | E23: - | J23: =SUM(J5:J22) -> 366.5 | K23: =AVERAGE(K5:K22) -> 1110.5556 | L23: =COUNTIF(L5:L22, "Evet")/COUNTA(L5:L22) -> 0.83333333 | M23: =SUM(M5:M22) -> 155748.9 | N23: =SUM(N5:N22) -> 31149.78 | O23: =SUM(O5:O22) -> 124599.12 | P23: - | Q23: =SUM(Q5:Q22) -> 75591.07 | R23: =SUM(R5:R22) -> 49008.05 | S23: =SUM(S5:S22) -> 0

Sheet Yönetim_Özeti_KPI
A1: ÜLKE MÜDÜRLÜKLERİ YÖNETİM ÖZETİ VE AĞIRLIKLANDIRILMIŞ KPI HEDEF KARTI
A2: Konsolide kâr paylaşım mutabakatı, %50 Finansal - %30 Operasyonel - %20 Stratejik ağırlıklı performans ve prim modeli.
A4: Toplam Üretilen Brüt Kâr | C4: TR Hub Stratejik Fonu (%20) | E4: Şubelere Dağıtılan Net Kâr | G4: Filo Ort. Zamanında Teslimat (OTD) | I4: Toplam Taşınan Yük Tonajı
A5: ='İşlemler'!M23 -> 155748.9 | C5: ='İşlemler'!N23 -> 31149.78 | E5: =SUM('İşlemler'!Q23, 'İşlemler'!R23) -> 124599.12 | G5: ='İşlemler'!L23 -> 0.83333333 | I5: ='İşlemler'!J23 -> 366.5
A7: BÖLÜM 1: ŞUBE VE ÜLKE MÜDÜRÜ KÂR VE HACİM KONSOLİDASYONU
A8: Şube Kodu | B8: Şube Adı | C8: Ülke Müdürü | D8: Satan Şube Kârı (€) | E8: Operasyon Şube Kârı (€) | F8: TR Hub Payı (€) | G8: Toplam Şube Kârı (€) | H8: Toplam İşlem Seferi | I8: Elleçlenen Tonaj (Ton)
A9: DE-MUC | B9: Almanya Şubesi | C9: Alman Müdür | D9: =SUMIFS('İşlemler'!$Q$5:$Q$22, 'İşlemler'!$F$5:$F$22, A9) -> 16954.4 | E9: =SUMIFS('İşlemler'!$R$5:$R$22, 'İşlemler'!$H$5:$H$22, A9) -> 8861.76 | F9: =IF(A9="TR-IST", 'İşlemler'!$N$23, 0) -> 0 | G9: =SUM(D9:F9) -> 25816.16 | H9: =COUNTIF('İşlemler'!$F$5:$F$22, A9) + COUNTIF('İşlemler'!$H$5:$H$22, A9) -> 8 | I9: =SUMIFS('İşlemler'!$J$5:$J$22, 'İşlemler'!$F$5:$F$22, A9) + SUMIFS('İşlemler'!$J$5:$J$22, 'İşlemler'!$H$5:$H$22, A9, 'İşlemler'!$F$5:$F$22, "<>"&A9) -> 146
A10: IT-MIL | B10: İtalya Şubesi | C10: İtalyan Müdür | D10: =SUMIFS('İşlemler'!$Q$5:$Q$22, 'İşlemler'!$F$5:$F$22, A10) -> 5467.44 | E10: =SUMIFS('İşlemler'!$R$5:$R$22, 'İşlemler'!$H$5:$H$22, A10) -> 6115.2 | F10: =IF(A10="TR-IST", 'İşlemler'!$N$23, 0) -> 0 | G10: =SUM(D10:F10) -> 11582.64 | H10: =COUNTIF('İşlemler'!$F$5:$F$22, A10) + COUNTIF('İşlemler'!$H$5:$H$22, A10) -> 4 | I10: =SUMIFS('İşlemler'!$J$5:$J$22, 'İşlemler'!$F$5:$F$22, A10) + SUMIFS('İşlemler'!$J$5:$J$22, 'İşlemler'!$H$5:$H$22, A10, 'İşlemler'!$F$5:$F$22, "<>"&A10) -> 77
A11: FR-LYO | B11: Fransa Şubesi | C11: Fransız Müdür | D11: =SUMIFS('İşlemler'!$Q$5:$Q$22, 'İşlemler'!$F$5:$F$22, A11) -> 12368.93 | E11: =SUMIFS('İşlemler'!$R$5:$R$22, 'İşlemler'!$H$5:$H$22, A11) -> 3423.6 | F11: =IF(A11="TR-IST", 'İşlemler'!$N$23, 0) -> 0 | G11: =SUM(D11:F11) -> 15792.53 | H11: =COUNTIF('İşlemler'!$F$5:$F$22, A11) + COUNTIF('İşlemler'!$H$5:$H$22, A11) -> 5 | I11: =SUMIFS('İşlemler'!$J$5:$J$22, 'İşlemler'!$F$5:$F$22, A11) + SUMIFS('İşlemler'!$J$5:$J$22, 'İşlemler'!$H$5:$H$22, A11, 'İşlemler'!$F$5:$F$22, "<>"&A11) -> 73.5
A12: ES-MAD | B12: İspanya Şubesi | C12: İspanyol Müdür | D12: =SUMIFS('İşlemler'!$Q$5:$Q$22, 'İşlemler'!$F$5:$F$22, A12) -> 10471.2 | E12: =SUMIFS('İşlemler'!$R$5:$R$22, 'İşlemler'!$H$5:$H$22, A12) -> 4106.4 | F12: =IF(A12="TR-IST", 'İşlemler'!$N$23, 0) -> 0 | G12: =SUM(D12:F12) -> 14577.6 | H12: =COUNTIF('İşlemler'!$F$5:$F$22, A12) + COUNTIF('İşlemler'!$H$5:$H$22, A12) -> 4 | I12: =SUMIFS('İşlemler'!$J$5:$J$22, 'İşlemler'!$F$5:$F$22, A12) + SUMIFS('İşlemler'!$J$5:$J$22, 'İşlemler'!$H$5:$H$22, A12, 'İşlemler'!$F$5:$F$22, "<>"&A12) -> 58
A13: PL-WAW | B13: Polonya Şubesi | C13: Polonyalı Müdür | D13: =SUMIFS('İşlemler'!$Q$5:$Q$22, 'İşlemler'!$F$5:$F$22, A13) -> 8572.7 | E13: =SUMIFS('İşlemler'!$R$5:$R$22, 'İşlemler'!$H$5:$H$22, A13) -> 8459.55 | F13: =IF(A13="TR-IST", 'İşlemler'!$N$23, 0) -> 0 | G13: =SUM(D13:F13) -> 17032.25 | H13: =COUNTIF('İşlemler'!$F$5:$F$22, A13) + COUNTIF('İşlemler'!$H$5:$H$22, A13) -> 5 | I13: =SUMIFS('İşlemler'!$J$5:$J$22, 'İşlemler'!$F$5:$F$22, A13) + SUMIFS('İşlemler'!$J$5:$J$22, 'İşlemler'!$H$5:$H$22, A13, 'İşlemler'!$F$5:$F$22, "<>"&A13) -> 97.5
A14: RO-BUC | B14: Romanya Şubesi | C14: Romanyalı Müdür | D14: =SUMIFS('İşlemler'!$Q$5:$Q$22, 'İşlemler'!$F$5:$F$22, A14) -> 8179.2 | E14: =SUMIFS('İşlemler'!$R$5:$R$22, 'İşlemler'!$H$5:$H$22, A14) -> 11739.94 | F14: =IF(A14="TR-IST", 'İşlemler'!$N$23, 0) -> 0 | G14: =SUM(D14:F14) -> 19919.14 | H14: =COUNTIF('İşlemler'!$F$5:$F$22, A14) + COUNTIF('İşlemler'!$H$5:$H$22, A14) -> 5 | I14: =SUMIFS('İşlemler'!$J$5:$J$22, 'İşlemler'!$F$5:$F$22, A14) + SUMIFS('İşlemler'!$J$5:$J$22, 'İşlemler'!$H$5:$H$22, A14, 'İşlemler'!$F$5:$F$22, "<>"&A14) -> 107
A15: TR-IST | B15: Türkiye Hub | C15: Türk Müdür | D15: =SUMIFS('İşlemler'!$Q$5:$Q$22, 'İşlemler'!$F$5:$F$22, A15) -> 13577.2 | E15: =SUMIFS('İşlemler'!$R$5:$R$22, 'İşlemler'!$H$5:$H$22, A15) -> 6301.6 | F15: =IF(A15="TR-IST", 'İşlemler'!$N$23, 0) -> 31149.78 | G15: =SUM(D15:F15) -> 51028.58 | H15: =COUNTIF('İşlemler'!$F$5:$F$22, A15) + COUNTIF('İşlemler'!$H$5:$H$22, A15) -> 5 | I15: =SUMIFS('İşlemler'!$J$5:$J$22, 'İşlemler'!$F$5:$F$22, A15) + SUMIFS('İşlemler'!$J$5:$J$22, 'İşlemler'!$H$5:$H$22, A15, 'İşlemler'!$F$5:$F$22, "<>"&A15) -> 115
A16: GENEL TOPLAM | D16: =SUM(D9:D15) -> 75591.07 | E16: =SUM(E9:E15) -> 49008.05 | F16: =SUM(F9:F15) -> 31149.78 | G16: =SUM(G9:G15) -> 155748.9 | H16: =SUM(H9:H15) -> 36 | I16: =SUM(I9:I15) -> 674
A18: BÖLÜM 2: NİHAİ 3 KUTULU ŞUBE MÜDÜRÜ PRİM SCORECARD TABLOSU
A19: Toplam Prim Modeli = [KUTU 1: Merdivenli Finansal Büyüme (%90-%125)] + [KUTU 2: Hacim x OTD Kalite Çarpanı (>=%90 Finansal Baraj)] + [KUTU 3: Sabit Stratejik Bounty]
A20: GENEL BİLGİLER | D20: KUTU 1: MERDİVENLİ FİNANSAL BÜYÜME (YoY) | H20: KUTU 2: HACİM X OTD KALİTE ÇARPANI | M20: KUTU 3: STRATEJİK BOUNTY GÖREVLERİ | P20: TOPLAM PRİM
A21: Şube Kodu | B21: Ülke Müdürü | C21: Gerçekleşen Kâr (€) | D21: Geçen Yıl Kârı (€) | E21: YoY Büyüme (%) | F21: Kutu 1 Oranı (%) | G21: KUTU 1 Prim (€) | H21: Elleçlenen Tonaj (Ton) | I21: Gerçekleşen OTD (%) | J21: OTD Kalite Çarpanı | K21: Finansal Baraj (>=%90) | L21: KUTU 2 Prim (€) | M21: Boş Dönüş Oranı | N21: Özmal Filo Oranı | O21: KUTU 3 Bounty (€) | P21: TOPLAM HAK EDİLEN PRİM (€)
A22: DE-MUC | B22: =C9 -> Alman Müdür | C22: =G9 -> 25816.16 | D22: {=_xlfn.XLOOKUP(A22, Parametreler!$A$22:$A$28, Parametreler!$I$22:$I$28)} -> 25000 | E22: =C22/D22 -> 1.0326464 | F22: =IF(E22<Parametreler!$B$34, 0, IF(E22<Parametreler!$B$35, Parametreler!$D$34, IF(E22<Parametreler!$B$36, Parametreler!$D$35, IF(E22<=Parametreler!$C$36, Parametreler!$D$36, 0)))) -> 0.1 | G22: =ROUND(C22*F22, 2) -> 2581.62 | H22: =I9 -> 146 | I22: =IFERROR(COUNTIFS('İşlemler'!$H$5:$H$22, A22, 'İşlemler'!$L$5:$L$22, "Evet") / COUNTIF('İşlemler'!$H$5:$H$22, A22), 1) -> 0.75 | J22: =IFS(I22>=0.95, Parametreler!$C$43, I22>=0.9, Parametreler!$C$44, I22>=0.85, Parametreler!$C$45, TRUE, Parametreler!$C$46) -> 0.5 | K22: =IF(E22>=Parametreler!$C$41, "Barajı Geçti", "Barajı Geçemedi") -> Barajı Geçti | L22: =IF(E22>=Parametreler!$C$41, ROUND(H22*Parametreler!$C$42*J22, 2), 0) -> 365 | M22: {=_xlfn.XLOOKUP(A22, Parametreler!$A$22:$A$28, Parametreler!$J$22:$J$28)} -> 0.105 | N22: {=_xlfn.XLOOKUP(A22, Parametreler!$A$22:$A$28, Parametreler!$K$22:$K$28)} -> 0.45 | O22: =(IF(M22<Parametreler!$C$50, Parametreler!$D$50, 0) + IF(N22>=Parametreler!$C$51, Parametreler!$D$51, 0)) -> 1500 | P22: =G22+L22+O22 -> 4446.62
A23: IT-MIL | B23: =C10 -> İtalyan Müdür | C23: =G10 -> 11582.64 | D23: {=_xlfn.XLOOKUP(A23, Parametreler!$A$22:$A$28, Parametreler!$I$22:$I$28)} -> 13500 | E23: =C23/D23 -> 0.85797333 | F23: =IF(E23<Parametreler!$B$34, 0, IF(E23<Parametreler!$B$35, Parametreler!$D$34, IF(E23<Parametreler!$B$36, Parametreler!$D$35, IF(E23<=Parametreler!$C$36, Parametreler!$D$36, 0)))) -> 0 | G23: =ROUND(C23*F23, 2) -> 0 | H23: =I10 -> 77 | I23: =IFERROR(COUNTIFS('İşlemler'!$H$5:$H$22, A23, 'İşlemler'!$L$5:$L$22, "Evet") / COUNTIF('İşlemler'!$H$5:$H$22, A23), 1) -> 1 | J23: =IFS(I23>=0.95, Parametreler!$C$43, I23>=0.9, Parametreler!$C$44, I23>=0.85, Parametreler!$C$45, TRUE, Parametreler!$C$46) -> 1.25 | K23: =IF(E23>=Parametreler!$C$41, "Barajı Geçti", "Barajı Geçemedi") -> Barajı Geçemedi | L23: =IF(E23>=Parametreler!$C$41, ROUND(H23*Parametreler!$C$42*J23, 2), 0) -> 0 | M23: {=_xlfn.XLOOKUP(A23, Parametreler!$A$22:$A$28, Parametreler!$J$22:$J$28)} -> 0.14 | N23: {=_xlfn.XLOOKUP(A23, Parametreler!$A$22:$A$28, Parametreler!$K$22:$K$28)} -> 0.42 | O23: =(IF(M23<Parametreler!$C$50, Parametreler!$D$50, 0) + IF(N23>=Parametreler!$C$51, Parametreler!$D$51, 0)) -> 750 | P23: =G23+L23+O23 -> 750
A24: FR-LYO | B24: =C11 -> Fransız Müdür | C24: =G11 -> 15792.53 | D24: {=_xlfn.XLOOKUP(A24, Parametreler!$A$22:$A$28, Parametreler!$I$22:$I$28)} -> 16500 | E24: =C24/D24 -> 0.95712303 | F24: =IF(E24<Parametreler!$B$34, 0, IF(E24<Parametreler!$B$35, Parametreler!$D$34, IF(E24<Parametreler!$B$36, Parametreler!$D$35, IF(E24<=Parametreler!$C$36, Parametreler!$D$36, 0)))) -> 0.05 | G24: =ROUND(C24*F24, 2) -> 789.63 | H24: =I11 -> 73.5 | I24: =IFERROR(COUNTIFS('İşlemler'!$H$5:$H$22, A24, 'İşlemler'!$L$5:$L$22, "Evet") / COUNTIF('İşlemler'!$H$5:$H$22, A24), 1) -> 1 | J24: =IFS(I24>=0.95, Parametreler!$C$43, I24>=0.9, Parametreler!$C$44, I24>=0.85, Parametreler!$C$45, TRUE, Parametreler!$C$46) -> 1.25 | K24: =IF(E24>=Parametreler!$C$41, "Barajı Geçti", "Barajı Geçemedi") -> Barajı Geçti | L24: =IF(E24>=Parametreler!$C$41, ROUND(H24*Parametreler!$C$42*J24, 2), 0) -> 459.38 | M24: {=_xlfn.XLOOKUP(A24, Parametreler!$A$22:$A$28, Parametreler!$J$22:$J$28)} -> 0.11 | N24: {=_xlfn.XLOOKUP(A24, Parametreler!$A$22:$A$28, Parametreler!$K$22:$K$28)} -> 0.38 | O24: =(IF(M24<Parametreler!$C$50, Parametreler!$D$50, 0) + IF(N24>=Parametreler!$C$51, Parametreler!$D$51, 0)) -> 750 | P24: =G24+L24+O24 -> 1999.01
A25: ES-MAD | B25: =C12 -> İspanyol Müdür | C25: =G12 -> 14577.6 | D25: {=_xlfn.XLOOKUP(A25, Parametreler!$A$22:$A$28, Parametreler!$I$22:$I$28)} -> 12000 | E25: =C25/D25 -> 1.2148 | F25: =IF(E25<Parametreler!$B$34, 0, IF(E25<Parametreler!$B$35, Parametreler!$D$34, IF(E25<Parametreler!$B$36, Parametreler!$D$35, IF(E25<=Parametreler!$C$36, Parametreler!$D$36, 0)))) -> 0.15 | G25: =ROUND(C25*F25, 2) -> 2186.64 | H25: =I12 -> 58 | I25: =IFERROR(COUNTIFS('İşlemler'!$H$5:$H$22, A25, 'İşlemler'!$L$5:$L$22, "Evet") / COUNTIF('İşlemler'!$H$5:$H$22, A25), 1) -> 1 | J25: =IFS(I25>=0.95, Parametreler!$C$43, I25>=0.9, Parametreler!$C$44, I25>=0.85, Parametreler!$C$45, TRUE, Parametreler!$C$46) -> 1.25 | K25: =IF(E25>=Parametreler!$C$41, "Barajı Geçti", "Barajı Geçemedi") -> Barajı Geçti | L25: =IF(E25>=Parametreler!$C$41, ROUND(H25*Parametreler!$C$42*J25, 2), 0) -> 362.5 | M25: {=_xlfn.XLOOKUP(A25, Parametreler!$A$22:$A$28, Parametreler!$J$22:$J$28)} -> 0.095 | N25: {=_xlfn.XLOOKUP(A25, Parametreler!$A$22:$A$28, Parametreler!$K$22:$K$28)} -> 0.48 | O25: =(IF(M25<Parametreler!$C$50, Parametreler!$D$50, 0) + IF(N25>=Parametreler!$C$51, Parametreler!$D$51, 0)) -> 1500 | P25: =G25+L25+O25 -> 4049.14
A26: PL-WAW | B26: =C13 -> Polonyalı Müdür | C26: =G13 -> 17032.25 | D26: {=_xlfn.XLOOKUP(A26, Parametreler!$A$22:$A$28, Parametreler!$I$22:$I$28)} -> 20500 | E26: =C26/D26 -> 0.83084146 | F26: =IF(E26<Parametreler!$B$34, 0, IF(E26<Parametreler!$B$35, Parametreler!$D$34, IF(E26<Parametreler!$B$36, Parametreler!$D$35, IF(E26<=Parametreler!$C$36, Parametreler!$D$36, 0)))) -> 0 | G26: =ROUND(C26*F26, 2) -> 0 | H26: =I13 -> 97.5 | I26: =IFERROR(COUNTIFS('İşlemler'!$H$5:$H$22, A26, 'İşlemler'!$L$5:$L$22, "Evet") / COUNTIF('İşlemler'!$H$5:$H$22, A26), 1) -> 0.66666667 | J26: =IFS(I26>=0.95, Parametreler!$C$43, I26>=0.9, Parametreler!$C$44, I26>=0.85, Parametreler!$C$45, TRUE, Parametreler!$C$46) -> 0.5 | K26: =IF(E26>=Parametreler!$C$41, "Barajı Geçti", "Barajı Geçemedi") -> Barajı Geçemedi | L26: =IF(E26>=Parametreler!$C$41, ROUND(H26*Parametreler!$C$42*J26, 2), 0) -> 0 | M26: {=_xlfn.XLOOKUP(A26, Parametreler!$A$22:$A$28, Parametreler!$J$22:$J$28)} -> 0.132 | N26: {=_xlfn.XLOOKUP(A26, Parametreler!$A$22:$A$28, Parametreler!$K$22:$K$28)} -> 0.35 | O26: =(IF(M26<Parametreler!$C$50, Parametreler!$D$50, 0) + IF(N26>=Parametreler!$C$51, Parametreler!$D$51, 0)) -> 0 | P26: =G26+L26+O26 -> 0
A27: RO-BUC | B27: =C14 -> Romanyalı Müdür | C27: =G14 -> 19919.14 | D27: {=_xlfn.XLOOKUP(A27, Parametreler!$A$22:$A$28, Parametreler!$I$22:$I$28)} -> 15500 | E27: =C27/D27 -> 1.2851058 | F27: =IF(E27<Parametreler!$B$34, 0, IF(E27<Parametreler!$B$35, Parametreler!$D$34, IF(E27<Parametreler!$B$36, Parametreler!$D$35, IF(E27<=Parametreler!$C$36, Parametreler!$D$36, 0)))) -> 0 | G27: =ROUND(C27*F27, 2) -> 0 | H27: =I14 -> 107 | I27: =IFERROR(COUNTIFS('İşlemler'!$H$5:$H$22, A27, 'İşlemler'!$L$5:$L$22, "Evet") / COUNTIF('İşlemler'!$H$5:$H$22, A27), 1) -> 0.66666667 | J27: =IFS(I27>=0.95, Parametreler!$C$43, I27>=0.9, Parametreler!$C$44, I27>=0.85, Parametreler!$C$45, TRUE, Parametreler!$C$46) -> 0.5 | K27: =IF(E27>=Parametreler!$C$41, "Barajı Geçti", "Barajı Geçemedi") -> Barajı Geçti | L27: =IF(E27>=Parametreler!$C$41, ROUND(H27*Parametreler!$C$42*J27, 2), 0) -> 267.5 | M27: {=_xlfn.XLOOKUP(A27, Parametreler!$A$22:$A$28, Parametreler!$J$22:$J$28)} -> 0.115 | N27: {=_xlfn.XLOOKUP(A27, Parametreler!$A$22:$A$28, Parametreler!$K$22:$K$28)} -> 0.52 | O27: =(IF(M27<Parametreler!$C$50, Parametreler!$D$50, 0) + IF(N27>=Parametreler!$C$51, Parametreler!$D$51, 0)) -> 1500 | P27: =G27+L27+O27 -> 1767.5
A28: TR-IST | B28: =C15 -> Türk Müdür | C28: =G15 -> 51028.58 | D28: {=_xlfn.XLOOKUP(A28, Parametreler!$A$22:$A$28, Parametreler!$I$22:$I$28)} -> 47000 | E28: =C28/D28 -> 1.0857145 | F28: =IF(E28<Parametreler!$B$34, 0, IF(E28<Parametreler!$B$35, Parametreler!$D$34, IF(E28<Parametreler!$B$36, Parametreler!$D$35, IF(E28<=Parametreler!$C$36, Parametreler!$D$36, 0)))) -> 0.1 | G28: =ROUND(C28*F28, 2) -> 5102.86 | H28: =I15 -> 115 | I28: =IFERROR(COUNTIFS('İşlemler'!$H$5:$H$22, A28, 'İşlemler'!$L$5:$L$22, "Evet") / COUNTIF('İşlemler'!$H$5:$H$22, A28), 1) -> 1 | J28: =IFS(I28>=0.95, Parametreler!$C$43, I28>=0.9, Parametreler!$C$44, I28>=0.85, Parametreler!$C$45, TRUE, Parametreler!$C$46) -> 1.25 | K28: =IF(E28>=Parametreler!$C$41, "Barajı Geçti", "Barajı Geçemedi") -> Barajı Geçti | L28: =IF(E28>=Parametreler!$C$41, ROUND(H28*Parametreler!$C$42*J28, 2), 0) -> 718.75 | M28: {=_xlfn.XLOOKUP(A28, Parametreler!$A$22:$A$28, Parametreler!$J$22:$J$28)} -> 0.08 | N28: {=_xlfn.XLOOKUP(A28, Parametreler!$A$22:$A$28, Parametreler!$K$22:$K$28)} -> 0.6 | O28: =(IF(M28<Parametreler!$C$50, Parametreler!$D$50, 0) + IF(N28>=Parametreler!$C$51, Parametreler!$D$51, 0)) -> 1500 | P28: =G28+L28+O28 -> 7321.61
A29: GENEL TOPLAM | B29: - | C29: =SUM(C22:C28) -> 155748.9 | D29: =SUM(D22:D28) -> 150000 | E29: =AVERAGE(E22:E28) -> 1.0377435 | F29: - | G29: =SUM(G22:G28) -> 10660.75 | H29: =SUM(H22:H28) -> 674 | I29: =AVERAGE(I22:I28) -> 0.86904762 | J29: =AVERAGE(J22:J28) -> 0.92857143 | K29: - | L29: =SUM(L22:L28) -> 2173.13 | M29: =AVERAGE(M22:M28) -> 0.111 | N29: =AVERAGE(N22:N28) -> 0.45714286 | O29: =SUM(O22:O28) -> 7500 | P29: =SUM(P22:P28) -> 20333.88
